Workbook

Sheet Instructions
B2: BEAT THE BUFFET: K-Pot Value Analysis
B3: Data Collection Template
B6: 📐 Key Formulas
B7: Estimated Serving Size (oz) | C7: menu calories ÷ Caloric Density Midpoint for the item's category (from Calorie Density Ref sheet)
B8: Retail Price Per Ounce | C8: retail price ÷ (Retail Unit Size in oz); standardizes all retail prices to $/oz
B9: Retail Value Per Serving | C9: retail_price_per_ounce × Estimated_Serving_Size , a.k.a the grocery-equivalent $ value of one buffet portion
B10: Cost Recovery Ratio | C10: total retail value of food consumed ÷ Dinner Buffet Price (see Value Analysis sheet)
B12: 📝 Data Collection Notes
B13: Calorie Source | C13: Use projected calories printed on the K-Pot menu (Columbus, OH location)
B14: Retail Price Date | C14: Record prices on a single date (the date I collected this data and used it)
B15: Price Collection Date | C15: Note above
B16: Retail Sources | C16: H-Mart as golden standard. If not listed there, used Costco, Kroger, Walmart, Instacart and Wee
B17: Buffet Dinner Price | C17: Assuming Dinner price, no extra drinks, 20% tip

Sheet Menu Data
A1: Beat the Buffet - K-Pot Menu Data
A2: Unique ID | B2: Name as on menu | C2: Food category | D2: Taken from K-Pot menu | E2: Yes / No | F2: Yes / No | G2: Brief description | H2: Derived from calories ÷ cal density | I2: Cal/oz midpoint used (from Ref sheet) | J2: Comparable grocery product | K2: Retail price ($) | L2: Quantity | M2: lb, oz, package… | N2: g --> oz | O2: Unit size in oz (e.g. 16 for 1 lb) | P2: retail_price ÷ Retail_Unit_Size_oz | Q2: price_per_oz × Est_Serving_Size_oz | R2: Any notes or caveats
A3: Item_ID | B3: Food_Name | C3: Category | D3: Calories | E3: Spicy | F3: Dinner_Item | G3: Description | H3: Est_Serving_Size_oz | I3: Cal_Density_Used | J3: Retail_Equivalent | K3: Retail_Price | L3: Quantity | M3: Unit | N3: Unit_Conversion(g) | O3: Retail_Unit_Size_oz | P3: Retail_Price_Per_Oz | Q3: Retail_Value_Per_Serving | R3: Notes
A4: 1 | B4: Beef Bulgogi | C4: Beef | D4: 180 | E4: No | F4: No | G4: Marinated beef | H4: =IF(AND(D4<>"",I4<>"",ISNUMBER(I4)),ROUND(D4/I4,1),"") -> 3.1 | I4: 57.5 | J4: Marinated Beef Thin Ribeye Roll Bulgogi | K4: 37.99 | L4: 907 | M4: g | N4: =L4/28.3495 -> 31.99351 | O4: =ROUND(N4,0) -> 32 | P4: =IF(AND(K4<>"",O4<>"",O4<>0),ROUND(K4/O4,4),"") -> 1.1872 | Q4: =IF(AND(P4<>"",H4<>"",ISNUMBER(P4)),ROUND(P4*H4,2),"") -> 3.68 | R4: 2 lb 907g = 32oz
A5: 2 | B5: Spicy Beef Bulgogi | C5: Beef | D5: 200 | E5: Yes | F5: No | G5: Marinated beef with spicy sauce | H5: =IF(AND(D5<>"",I5<>"",ISNUMBER(I5)),ROUND(D5/I5,1),"") -> 3.5 | I5: 57.5 | J5: Marinated Beef Spicy Ribeye Roll Bulgogi | K5: 12.99 | L5: 454 | M5: g | N5: =L5/28.3495 -> 16.014392 | O5: =ROUND(N5,0) -> 16 | P5: =IF(AND(K5<>"",O5<>"",O5<>0),ROUND(K5/O5,4),"") -> 0.8119 | Q5: =IF(AND(P5<>"",H5<>"",ISNUMBER(P5)),ROUND(P5*H5,2),"") -> 2.84 | R5: 1 lb 454g = 16oz
A6: 3 | B6: Prime Brisket | C6: Beef | D6: 230 | E6: No | F6: No | G6: Thinly Sliced Prime Brisket | H6: =IF(AND(D6<>"",I6<>"",ISNUMBER(I6)),ROUND(D6/I6,1),"") -> 4 | I6: 57.5 | J6: Beef Thin&Roll Brisket Choice | K6: 12.99 | L6: 454 | M6: g | N6: =L6/28.3495 -> 16.014392 | O6: =ROUND(N6,0) -> 16 | P6: =IF(AND(K6<>"",O6<>"",O6<>0),ROUND(K6/O6,4),"") -> 0.8119 | Q6: =IF(AND(P6<>"",H6<>"",ISNUMBER(P6)),ROUND(P6*H6,2),"") -> 3.25 | R6: 1lb 454g = 16oz
A7: 4 | B7: Sliced Beef Belly | C7: Beef | D7: 360 | E7: No | F7: No | G7: Sliced Beef Belly | H7: =IF(AND(D7<>"",I7<>"",ISNUMBER(I7)),ROUND(D7/I7,1),"") -> 5 | I7: 72.5 | J7: Beef Thin&Roll Boneless Short Plate | K7: 9.79 | L7: 454 | M7: g | N7: =L7/28.3495 -> 16.014392 | O7: =ROUND(N7,0) -> 16 | P7: =IF(AND(K7<>"",O7<>"",O7<>0),ROUND(K7/O7,4),"") -> 0.6119 | Q7: =IF(AND(P7<>"",H7<>"",ISNUMBER(P7)),ROUND(P7*H7,2),"") -> 3.06
A8: 5 | B8: Sliced Beef Tongue | C8: Beef | D8: 190 | E8: No | F8: Yes | G8: Sliced Beef Tongue | H8: =IF(AND(D8<>"",I8<>"",ISNUMBER(I8)),ROUND(D8/I8,1),"") -> 2.6 | I8: 72.5 | J8: Beef Thin&Roll Tongue | K8: 25.99 | L8: 454 | M8: g | N8: =L8/28.3495 -> 16.014392 | O8: =ROUND(N8,0) -> 16 | P8: =IF(AND(K8<>"",O8<>"",O8<>0),ROUND(K8/O8,4),"") -> 1.6244 | Q8: =IF(AND(P8<>"",H8<>"",ISNUMBER(P8)),ROUND(P8*H8,2),"") -> 4.22
A9: 6 | B9: K-POT Steak | C9: Beef | D9: 280 | E9: No | F9: Yes | G9: USDA Grade Steak | H9: =IF(AND(D9<>"",I9<>"",ISNUMBER(I9)),ROUND(D9/I9,1),"") -> 3.9 | I9: 72.5 | J9: Great Southern Grass Fed Beef, ABF NY Strip CC Steak | K9: 22.86 | L9: 340 | M9: g | N9: =L9/28.3495 -> 11.993157 | O9: =ROUND(N9,0) -> 12 | P9: =IF(AND(K9<>"",O9<>"",O9<>0),ROUND(K9/O9,4),"") -> 1.905 | Q9: =IF(AND(P9<>"",H9<>"",ISNUMBER(P9)),ROUND(P9*H9,2),"") -> 7.43 | R9: 12oz. Found on Costco
A10: 7 | B10: Finger Ribs | C10: Beef | D10: 240 | E10: No | F10: No | G10: Finger Ribs | H10: =IF(AND(D10<>"",I10<>"",ISNUMBER(I10)),ROUND(D10/I10,1),"") -> 3.3 | I10: 72.5 | J10: Beef /short Ribs /finger Meat | K10: 11.99 | L10: 453 | M10: g | N10: =L10/28.3495 -> 15.979118 | O10: =ROUND(N10,0) -> 16 | P10: =IF(AND(K10<>"",O10<>"",O10<>0),ROUND(K10/O10,4),"") -> 0.7494 | Q10: =IF(AND(P10<>"",H10<>"",ISNUMBER(P10)),ROUND(P10*H10,2),"") -> 2.47
A11: 8 | B11: KPOT Short Rib | C11: Beef | D11: 300 | E11: No | F11: Yes | G11: Marinated short rib | H11: =IF(AND(D11<>"",I11<>"",ISNUMBER(I11)),ROUND(D11/I11,1),"") -> 4.1 | I11: 72.5 | J11: Marinated Sliced Beef Short Rib(La Galbi) | K11: 18.99 | L11: 454 | M11: g | N11: =L11/28.3495 -> 16.014392 | O11: =ROUND(N11,0) -> 16 | P11: =IF(AND(K11<>"",O11<>"",O11<>0),ROUND(K11/O11,4),"") -> 1.1869 | Q11: =IF(AND(P11<>"",H11<>"",ISNUMBER(P11)),ROUND(P11*H11,2),"") -> 4.87
A12: 9 | B12: Angus Chuck Flap Tail | C12: Beef | D12: 240 | E12: No | F12: Yes | G12: Angus Chuck Flap Tail | H12: =IF(AND(D12<>"",I12<>"",ISNUMBER(I12)),ROUND(D12/I12,1),"") -> 3.3 | I12: 72.5 | J12: Usda Choice Beef Sliced Chuck Flap Tail | K12: 23.49 | L12: 227 | M12: g | N12: =L12/28.3495 -> 8.0071959 | O12: =ROUND(N12,0) -> 8 | P12: =IF(AND(K12<>"",O12<>"",O12<>0),ROUND(K12/O12,4),"") -> 2.9363 | Q12: =IF(AND(P12<>"",H12<>"",ISNUMBER(P12)),ROUND(P12*H12,2),"") -> 9.69
A13: 10 | B13: Chicken Bulgogi | C13: Chicken | D13: 120 | E13: No | F13: No | G13: Boneless chicken | H13: =IF(AND(D13<>"",I13<>"",ISNUMBER(I13)),ROUND(D13/I13,1),"") -> 2.4 | I13: 50 | J13: KBBQ Premium Soy Chicken Bulgogi | K13: 15.99 | L13: 907 | M13: g | N13: =L13/28.3495 -> 31.99351 | O13: =ROUND(N13,0) -> 32 | P13: =IF(AND(K13<>"",O13<>"",O13<>0),ROUND(K13/O13,4),"") -> 0.4997 | Q13: =IF(AND(P13<>"",H13<>"",ISNUMBER(P13)),ROUND(P13*H13,2),"") -> 1.2 | R13: 2lbs. Taken from https://www.sayweee.com/en/product/KBBQ-Premium-Soy-Chicken-Bulgogi/108808?utm_source=seo-explore&utm_campaign=top-seo-expanded-1&utm_content=product-108808&checkZip=true&fbp=fb.1.1782235153751.624890839479713468.AQYAAQIB&mt=8
A14: 11 | B14: Spicy Chicken Bulgogi | C14: Chicken | D14: 130 | E14: Yes | F14: No | G14: Boneless chicken with spicy sauce | H14: =IF(AND(D14<>"",I14<>"",ISNUMBER(I14)),ROUND(D14/I14,1),"") -> 2.6 | I14: 50 | J14: KBBQ Spicy Chicken Thigh Bulgogi | K14: 7.49 | L14: 340 | M14: g | N14: =L14/28.3495 -> 11.993157 | O14: =ROUND(N14,0) -> 12 | P14: =IF(AND(K14<>"",O14<>"",O14<>0),ROUND(K14/O14,4),"") -> 0.6242 | Q14: =IF(AND(P14<>"",H14<>"",ISNUMBER(P14)),ROUND(P14*H14,2),"") -> 1.62 | R14: Taken from https://www.sayweee.com/en/product/KBBQ-Spicy-Chicken-Thigh-Bulgogi--Frozen-1/91084
A15: 12 | B15: Garlic Chicken | C15: Chicken | D15: 150 | E15: No | F15: No | G15: Boneless chicken in garlic sauce | H15: =IF(AND(D15<>"",I15<>"",ISNUMBER(I15)),ROUND(D15/I15,1),"") -> 3 | I15: 50 | J15: Bibigo Frozen Korean Style Crunchy Chicken with Soy Garlic Sauce | K15: 8.99 | L15: 510 | M15: g | N15: =L15/28.3495 -> 17.989735 | O15: =ROUND(N15,0) -> 18 | P15: =IF(AND(K15<>"",O15<>"",O15<>0),ROUND(K15/O15,4),"") -> 0.4994 | Q15: =IF(AND(P15<>"",H15<>"",ISNUMBER(P15)),ROUND(P15*H15,2),"") -> 1.5 | R15: Taken from https://www.instacart.com/products/27993071-bibigo-korean-style-crunchy-chicken-with-soy-garlic-sauce-18-oz?retailerSlug=dillons
A16: 13 | B16: Spicy Pork Bulgogi | C16: Pork | D16: 210 | E16: No | F16: Yes | G16: Marinated pork with spicy sauce | H16: =IF(AND(D16<>"",I16<>"",ISNUMBER(I16)),ROUND(D16/I16,1),"") -> 3.4 | I16: 62.5 | J16: Marinated Pork Spicy CT Butt Bulgogi | K16: 7.99 | L16: 454 | M16: g | N16: =L16/28.3495 -> 16.014392 | O16: =ROUND(N16,0) -> 16 | P16: =IF(AND(K16<>"",O16<>"",O16<>0),ROUND(K16/O16,4),"") -> 0.4994 | Q16: =IF(AND(P16<>"",H16<>"",ISNUMBER(P16)),ROUND(P16*H16,2),"") -> 1.7
A17: 14 | B17: Pork Belly | C17: Pork | D17: 330 | E17: No | F17: No | G17: Regular style sliced pork belly | H17: =IF(AND(D17<>"",I17<>"",ISNUMBER(I17)),ROUND(D17/I17,1),"") -> 3.6 | I17: 92.5 | J17: Sliced Single Pork Belly, Frozen | K17: 13.99 | L17: 907 | M17: g | N17: =L17/28.3495 -> 31.99351 | O17: =ROUND(N17,0) -> 32 | P17: =IF(AND(K17<>"",O17<>"",O17<>0),ROUND(K17/O17,4),"") -> 0.4372 | Q17: =IF(AND(P17<>"",H17<>"",ISNUMBER(P17)),ROUND(P17*H17,2),"") -> 1.57
A18: 15 | B18: Spicy Pork Belly | C18: Pork | D18: 330 | E18: Yes | F18: No | G18: Marinated pork belly with spicy sauce | H18: =IF(AND(D18<>"",I18<>"",ISNUMBER(I18)),ROUND(D18/I18,1),"") -> 3.6 | I18: 92.5 | J18: Marinated Pork Sliced Single Belly | K18: 15.99 | L18: 907 | M18: g | N18: =L18/28.3495 -> 31.99351 | O18: =ROUND(N18,0) -> 32 | P18: =IF(AND(K18<>"",O18<>"",O18<>0),ROUND(K18/O18,4),"") -> 0.4997 | Q18: =IF(AND(P18<>"",H18<>"",ISNUMBER(P18)),ROUND(P18*H18,2),"") -> 1.8
A19: 16 | B19: Smoked Garlic Pork Belly | C19: Pork | D19: 320 | E19: No | F19: No | G19: Smoked & marinated pork belly with garlic sauce | H19: =IF(AND(D19<>"",I19<>"",ISNUMBER(I19)),ROUND(D19/I19,1),"") -> 3.5 | I19: 92.5 | J19: Marinated Pork Sliced Single Belly | K19: 15.99 | L19: 907 | M19: g | N19: =L19/28.3495 -> 31.99351 | O19: =ROUND(N19,0) -> 32 | P19: =IF(AND(K19<>"",O19<>"",O19<>0),ROUND(K19/O19,4),"") -> 0.4997 | Q19: =IF(AND(P19<>"",H19<>"",ISNUMBER(P19)),ROUND(P19*H19,2),"") -> 1.75 | R19: Using same metric as Spicy Pork Belly due to lack of resources
A20: 17 | B20: KPOT Pork Belly | C20: Pork | D20: 340 | E20: No | F20: No | G20: Marinated premium pork belly | H20: =IF(AND(D20<>"",I20<>"",ISNUMBER(I20)),ROUND(D20/I20,1),"") -> 3.7 | I20: 92.5 | J20: Premium Pork Belly, Skin-On Boneless | K20: 13.99 | L20: 907 | M20: g | N20: =L20/28.3495 -> 31.99351 | O20: =ROUND(N20,0) -> 32 | P20: =IF(AND(K20<>"",O20<>"",O20<>0),ROUND(K20/O20,4),"") -> 0.4372 | Q20: =IF(AND(P20<>"",H20<>"",ISNUMBER(P20)),ROUND(P20*H20,2),"") -> 1.62 | R20: (Premium pork belly) Taken from https://www.sayweee.com/en/product/Premium-Pork-Belly-Skin-On-Boneless-Frozen-1/112265?utm_source=seo-explore&utm_campaign=top-seo-expanded-1&utm_content=product-112265&checkZip=true&fbp=fb.1.1782235153751.624890839479713468.AQYAAQIB&mt=8
A21: 18 | B21: Sliced Pork Belly | C21: Pork | D21: 330 | E21: No | F21: No | G21: Thinly Sliced Pork Belly | H21: =IF(AND(D21<>"",I21<>"",ISNUMBER(I21)),ROUND(D21/I21,1),"") -> 3.6 | I21: 92.5 | J21: Pork Thin&Roll Single Rib Belly, Frozen | K21: 7.99 | L21: 454 | M21: g | N21: =L21/28.3495 -> 16.014392 | O21: =ROUND(N21,0) -> 16 | P21: =IF(AND(K21<>"",O21<>"",O21<>0),ROUND(K21/O21,4),"") -> 0.4994 | Q21: =IF(AND(P21<>"",H21<>"",ISNUMBER(P21)),ROUND(P21*H21,2),"") -> 1.8
A22: 19 | B22: Spicy Calamari | C22: Seafood | D22: 110 | E22: Yes | F22: No | G22: Marinated calamari with spicy sauce | H22: =IF(AND(D22<>"",I22<>"",ISNUMBER(I22)),ROUND(D22/I22,1),"") -> 4.2 | I22: 26 | J22: Frozen Wild Caught Squid | K22: 6.99 | L22: 300 | M22: g | N22: =L22/28.3495 -> 10.582197 | O22: =ROUND(N22,0) -> 11 | P22: =IF(AND(K22<>"",O22<>"",O22<>0),ROUND(K22/O22,4),"") -> 0.6355 | Q22: =IF(AND(P22<>"",H22<>"",ISNUMBER(P22)),ROUND(P22*H22,2),"") -> 2.67 | R22: Small flucuation possible due to sauce. Took middle point of serving size present at https://www.sayweee.com/en/product/Frozen-Wild-Caught-Squid/107292?utm_source=seo-explore&utm_campaign=top-seo-expanded-1&utm_content=product-107292&checkZip=true&fbp=fb.1.1782235153751.624890839479713468.AQYAAQIB&mt=8
A23: 20 | B23: Spicy Fish Fillet | C23: Seafood | D23: 100 | E23: Yes | F23: No | G23: Marinated fish fillet with spicy sauce | H23: =IF(AND(D23<>"",I23<>"",ISNUMBER(I23)),ROUND(D23/I23,1),"") -> 3.3 | I23: 30 | J23: Tilapia Fillet | K23: 9.99 | L23: 311 | M23: g | N23: =L23/28.3495 -> 10.970211 | O23: =ROUND(N23,0) -> 11 | P23: =IF(AND(K23<>"",O23<>"",O23<>0),ROUND(K23/O23,4),"") -> 0.9082 | Q23: =IF(AND(P23<>"",H23<>"",ISNUMBER(P23)),ROUND(P23*H23,2),"") -> 3 | R23: Small flucuation possible due to sauce.
A24: 21 | B24: Mussels | C24: Seafood | D24: 80 | E24: No | F24: No | G24: Mussels | H24: =IF(AND(D24<>"",I24<>"",ISNUMBER(I24)),ROUND(D24/I24,1),"") -> 3.3 | I24: 24 | J24: Cooked Mussel Meat | K24: 5.99 | L24: 453 | M24: g | N24: =L24/28.3495 -> 15.979118 | O24: =ROUND(N24,0) -> 16 | P24: =IF(AND(K24<>"",O24<>"",O24<>0),ROUND(K24/O24,4),"") -> 0.3744 | Q24: =IF(AND(P24<>"",H24<>"",ISNUMBER(P24)),ROUND(P24*H24,2),"") -> 1.24
A25: 22 | B25: Garlic Shrimp | C25: Seafood | D25: 90 | E25: No | F25: No | G25: Marinated shrimp with garlic sauce | H25: =IF(AND(D25<>"",I25<>"",ISNUMBER(I25)),ROUND(D25/I25,1),"") -> 3 | I25: 30 | J25: Raw Shrimp | K25: 12.99 | L25: 454 | M25: g | N25: =L25/28.3495 -> 16.014392 | O25: =ROUND(N25,0) -> 16 | P25: =IF(AND(K25<>"",O25<>"",O25<>0),ROUND(K25/O25,4),"") -> 0.8119 | Q25: =IF(AND(P25<>"",H25<>"",ISNUMBER(P25)),ROUND(P25*H25,2),"") -> 2.44 | R25: Small flucuation possible due to marination
A26: 23 | B26: Jumbo Shrimp | C26: Seafood | D26: 90 | E26: No | F26: Yes | G26: Jumbo Shrimp | H26: =IF(AND(D26<>"",I26<>"",ISNUMBER(I26)),ROUND(D26/I26,1),"") -> 3 | I26: 30 | J26: Haven Foods Head On Jumbo Raw Shrimp | K26: 9.99 | L26: 907 | M26: g | N26: =L26/28.3495 -> 31.99351 | O26: =ROUND(N26,0) -> 32 | P26: =IF(AND(K26<>"",O26<>"",O26<>0),ROUND(K26/O26,4),"") -> 0.3122 | Q26: =IF(AND(P26<>"",H26<>"",ISNUMBER(P26)),ROUND(P26*H26,2),"") -> 0.94
A27: 24 | B27: Spicy Baby Octopus | C27: Seafood | D27: 90 | E27: Yes | F27: Yes | G27: Marinated baby octopus with spicy sauce | H27: =IF(AND(D27<>"",I27<>"",ISNUMBER(I27)),ROUND(D27/I27,1),"") -> 3.5 | I27: 26 | J27: Baby Octopus | K27: 13.99 | L27: 907 | M27: g | N27: =L27/28.3495 -> 31.99351 | O27: =ROUND(N27,0) -> 32 | P27: =IF(AND(K27<>"",O27<>"",O27<>0),ROUND(K27/O27,4),"") -> 0.4372 | Q27: =IF(AND(P27<>"",H27<>"",ISNUMBER(P27)),ROUND(P27*H27,2),"") -> 1.53 | R27: Small flucuation possible due to marination
A28: 25 | B28: Spicy Salmon | C28: Seafood | D28: 170 | E28: Yes | F28: Yes | G28: Marinated salmon with spicy sauce | H28: =IF(AND(D28<>"",I28<>"",ISNUMBER(I28)),ROUND(D28/I28,1),"") -> 4.3 | I28: 40 | J28: Sea Queen Fresh Atlantic Salmon Portions | K28: 8.99 | L28: 407 | M28: g | N28: =L28/28.3495 -> 14.356514 | O28: =ROUND(N28,0) -> 14 | P28: =IF(AND(K28<>"",O28<>"",O28<>0),ROUND(K28/O28,4),"") -> 0.6421 | Q28: =IF(AND(P28<>"",H28<>"",ISNUMBER(P28)),ROUND(P28*H28,2),"") -> 2.76 | R28: Small flucuation possible due to marination. Found from https://www.instacart.com/products/17771058-fresh-salmon-1-per-lb
A29: 26 | B29: Eggplant | C29: Vegetable | D29: 20 | E29: No | F29: No | G29: Eggplant | H29: =IF(AND(D29<>"",I29<>"",ISNUMBER(I29)),ROUND(D29/I29,1),"") -> 1.3 | I29: 15 | J29: Eggplant | K29: 1.99 | L29: 85 | M29: g | N29: =L29/28.3495 -> 2.9982892 | O29: =ROUND(N29,0) -> 3 | P29: =IF(AND(K29<>"",O29<>"",O29<>0),ROUND(K29/O29,4),"") -> 0.6633 | Q29: =IF(AND(P29<>"",H29<>"",ISNUMBER(P29)),ROUND(P29*H29,2),"") -> 0.86 | R29: Kroger
A30: 27 | B30: Pumpkin | C30: Vegetable | D30: 20 | E30: No | F30: No | G30: Pumpkin | H30: =IF(AND(D30<>"",I30<>"",ISNUMBER(I30)),ROUND(D30/I30,1),"") -> 1.3 | I30: 15 | J30: Kroger Pumpkin | K30: 3.29 | L30: 822 | M30: g | N30: =L30/28.3495 -> 28.99522 | O30: =ROUND(N30,0) -> 29 | P30: =IF(AND(K30<>"",O30<>"",O30<>0),ROUND(K30/O30,4),"") -> 0.1134 | Q30: =IF(AND(P30<>"",H30<>"",ISNUMBER(P30)),ROUND(P30*H30,2),"") -> 0.15 | R30: Kroger
A31: 28 | B31: Potato | C31: Vegetable | D31: 70 | E31: No | F31: No | G31: Potato | H31: =IF(AND(D31<>"",I31<>"",ISNUMBER(I31)),ROUND(D31/I31,1),"") -> 4.7 | I31: 15 | J31: Kroger® Russet Potatoes | K31: 0.74 | L31: 110 | M31: g | N31: =L31/28.3495 -> 3.880139 | O31: =ROUND(N31,0) -> 4 | P31: =IF(AND(K31<>"",O31<>"",O31<>0),ROUND(K31/O31,4),"") -> 0.185 | Q31: =IF(AND(P31<>"",H31<>"",ISNUMBER(P31)),ROUND(P31*H31,2),"") -> 0.87
A32: 29 | B32: Sweet Potato | C32: Vegetable | D32: 70 | E32: No | F32: No | G32: Sweet Potato | H32: =IF(AND(D32<>"",I32<>"",ISNUMBER(I32)),ROUND(D32/I32,1),"") -> 4.7 | I32: 15 | J32: Sweet Potato | K32: 1.04 | L32: 110 | M32: g | N32: =L32/28.3495 -> 3.880139 | O32: =ROUND(N32,0) -> 4 | P32: =IF(AND(K32<>"",O32<>"",O32<>0),ROUND(K32/O32,4),"") -> 0.26 | Q32: =IF(AND(P32<>"",H32<>"",ISNUMBER(P32)),ROUND(P32*H32,2),"") -> 1.22
A33: 30 | B33: Zucchini | C33: Vegetable | D33: 15 | E33: No | F33: No | G33: Zucchini | H33: =IF(AND(D33<>"",I33<>"",ISNUMBER(I33)),ROUND(D33/I33,1),"") -> 1 | I33: 15 | J33: Zucchini | K33: 0.9 | L33: 85 | M33: g | N33: =L33/28.3495 -> 2.9982892 | O33: =ROUND(N33,0) -> 3 | P33: =IF(AND(K33<>"",O33<>"",O33<>0),ROUND(K33/O33,4),"") -> 0.3 | Q33: =IF(AND(P33<>"",H33<>"",ISNUMBER(P33)),ROUND(P33*H33,2),"") -> 0.3
A34: 31 | B34: Pineapple | C34: Vegetable | D34: 45 | E34: No | F34: No | G34: Pineapple | H34: =IF(AND(D34<>"",I34<>"",ISNUMBER(I34)),ROUND(D34/I34,1),"") -> 2.8 | I34: 16 | J34: Fresh Ripe Whole Pineapple | K34: 2.99 | L34: 140 | M34: g | N34: =L34/28.3495 -> 4.9383587 | O34: =ROUND(N34,0) -> 5 | P34: =IF(AND(K34<>"",O34<>"",O34<>0),ROUND(K34/O34,4),"") -> 0.598 | Q34: =IF(AND(P34<>"",H34<>"",ISNUMBER(P34)),ROUND(P34*H34,2),"") -> 1.67
A35: 32 | B35: King Mushroom | C35: Vegetable | D35: 20 | E35: No | F35: No | G35: King Mushroom | H35: =IF(AND(D35<>"",I35<>"",ISNUMBER(I35)),ROUND(D35/I35,1),"") -> 1.3 | I35: 15 | J35: ORGANIC MINI KING OYSTER MUSHROOM KOREA | K35: 5.99 | L35: 300 | M35: g | N35: =L35/28.3495 -> 10.582197 | O35: =ROUND(N35,0) -> 11 | P35: =IF(AND(K35<>"",O35<>"",O35<>0),ROUND(K35/O35,4),"") -> 0.5445 | Q35: =IF(AND(P35<>"",H35<>"",ISNUMBER(P35)),ROUND(P35*H35,2),"") -> 0.71
A36: 33 | B36: Beech Mushroom | C36: Vegetable | D36: 15 | E36: No | F36: No | G36: Beech Mushroom | H36: =IF(AND(D36<>"",I36<>"",ISNUMBER(I36)),ROUND(D36/I36,1),"") -> 1 | I36: 15 | J36: Organic Bunashimeji Brown Beech Mushroom | K36: 2.99 | L36: 100 | M36: g | N36: =L36/28.3495 -> 3.5273991 | O36: =ROUND(N36,0) -> 4 | P36: =IF(AND(K36<>"",O36<>"",O36<>0),ROUND(K36/O36,4),"") -> 0.7475 | Q36: =IF(AND(P36<>"",H36<>"",ISNUMBER(P36)),ROUND(P36*H36,2),"") -> 0.75
A37: 34 | B37: Onion | C37: Vegetable | D37: 35 | E37: No | F37: No | G37: Onion | H37: =IF(AND(D37<>"",I37<>"",ISNUMBER(I37)),ROUND(D37/I37,1),"") -> 2.3 | I37: 15 | J37: Jumbo White Onions | K37: 0.65 | L37: 585 | M37: g | N37: =L37/28.3495 -> 20.635285 | O37: =ROUND(N37,0) -> 21 | P37: =IF(AND(K37<>"",O37<>"",O37<>0),ROUND(K37/O37,4),"") -> 0.031 | Q37: =IF(AND(P37<>"",H37<>"",ISNUMBER(P37)),ROUND(P37*H37,2),"") -> 0.07
A38: 35 | B38: Pepper | C38: Vegetable | D38: 25 | E38: No | F38: No | G38: Pepper | H38: =IF(AND(D38<>"",I38<>"",ISNUMBER(I38)),ROUND(D38/I38,1),"") -> 1.7 | I38: 15 | J38: Fresh Red Hothouse Bell Pepper | K38: 1.67 | L38: 85 | M38: g | N38: =L38/28.3495 -> 2.9982892 | O38: =ROUND(N38,0) -> 3 | P38: =IF(AND(K38<>"",O38<>"",O38<>0),ROUND(K38/O38,4),"") -> 0.5567 | Q38: =IF(AND(P38<>"",H38<>"",ISNUMBER(P38)),ROUND(P38*H38,2),"") -> 0.95 | R38: Slight price flucuation because pepper includes Red & Green peppers (green are slighly cheaper)
A39: 36 | B39: Green Leaf Lettace | C39: Vegetable | D39: 15 | E39: No | F39: No | G39: Green Leaf Lettace | H39: =IF(AND(D39<>"",I39<>"",ISNUMBER(I39)),ROUND(D39/I39,1),"") -> 1.5 | I39: 10 | J39: Fresh Green Leaf Lettuce | K39: 2.79 | L39: 85 | M39: g | N39: =L39/28.3495 -> 2.9982892 | O39: =ROUND(N39,0) -> 3 | P39: =IF(AND(K39<>"",O39<>"",O39<>0),ROUND(K39/O39,4),"") -> 0.93 | Q39: =IF(AND(P39<>"",H39<>"",ISNUMBER(P39)),ROUND(P39*H39,2),"") -> 1.4
A40: 37 | B40: Garlic | C40: Vegetable | D40: 130 | E40: No | F40: No | G40: Garlic | H40: =IF(AND(D40<>"",I40<>"",ISNUMBER(I40)),ROUND(D40/I40,1),"") -> 3 | I40: 43 | J40: Kroger® Peeled Garlic | K40: 2.99 | L40: 170 | M40: g | N40: =L40/28.3495 -> 5.9965784 | O40: =ROUND(N40,0) -> 6 | P40: =IF(AND(K40<>"",O40<>"",O40<>0),ROUND(K40/O40,4),"") -> 0.4983 | Q40: =IF(AND(P40<>"",H40<>"",ISNUMBER(P40)),ROUND(P40*H40,2),"") -> 1.49
...

Sheet Calorie Density Ref
B1: Caloric Density Reference - Serving Size Derivation
B2: Used the Midpoint value in column I (Cal_Density_Used) of the Menu Data sheet for each item.
B3: Food Category | C3: Cal/oz Low | D3: Cal/oz High | E3: Midpoint | F3: Notes
B4: Beef (lean, marinated/bulgogi) | C4: 50 | D4: 65 | E4: 57.5 | F4: Bulgogi, short rib, brisket. Note: marinade adds minor calories
B5: Beef (fatty cuts, e.g. galbi) | C5: 65 | D5: 80 | E5: 72.5 | F5: Higher fat content elevates calorie density
B6: Pork Belly | C6: 85 | D6: 100 | E6: 92.5 | F6: High fat - most calorie-dense item on menu
B7: Pork (lean, marinated) | C7: 55 | D7: 70 | E7: 62.5 | F7: Shoulder, loin cuts; lower than belly
B8: Chicken (boneless, marinated) | C8: 45 | D8: 55 | E8: 50 | F8: Lean; breast lower end, thigh upper end
B9: Shrimp | C9: 25 | D9: 35 | E9: 30 | F9: Very lean; low calorie density
B10: Squid / Octopus | C10: 22 | D10: 30 | E10: 26 | F10: Similar to shrimp
B11: Scallops / Clams | C11: 20 | D11: 28 | E11: 24 | F11: Lowest density seafood items
B12: Fish | C12: 35 | D12: 45 | E12: 40 | F12: Fatty (e.g. Salmon)
B13: Steamed Rice | C13: 32 | D13: 38 | E13: 35 | F13: Cooked weight; denser than raw
B14: Fruit | C14: 14 | D14: 18 | E14: 16 | F14: Fruits (e.g. Pineapple)
B15: Leafy Vegetables | C15: 5 | D15: 15 | E15: 10 | F15: Lettuce, spinach, perilla
... B17: Root Vegetables / Mushrooms | C17: 10 | D17: 20 | E17: 15 | F17: Onion, zucchini, mushrooms

Sheet Value Analysis
B1: Beat the Buffet - Value Analysis Summary
B3: ASSUMPTIONS
B4: Dinner Buffet Price (per person) | C4: 39.51 | D4: ← K-Pot Dinner Price (only KBBQ, no drinks, 20% tip included)
B5: Price Collection Date | C5: 46196 | D5: ← Date retail prices were collected
B7: DATASET SUMMARY (auto-calculated from Menu Data sheet)
B8: Total Menu Items | C8: =COUNTA('Menu Data'!B4:B86) -> 38
B9: Dinner-Only Items | C9: =COUNTIF('Menu Data'!F4:F86,"Yes") -> 8
B10: Items with Retail Value | C10: =COUNTA('Menu Data'!Q4:Q86) -> 83
B11: Avg Calories per Item | C11: =IFERROR(AVERAGE('Menu Data'!D4:D86),"") -> 152.63158
B12: Avg Retail Value/Serving | C12: =AVERAGE('Menu Data'!Q4:Q41) -> 2.14
B13: Total Retail Value (all) | C13: =SUM('Menu Data'!Q4:Q41) -> 81.32
B14: Highest Value Item | C14: =IFERROR(INDEX('Menu Data'!B4:B86,MATCH(MAX('Menu Data'!Q4:Q86),'Menu Data'!Q4:Q86,0)),"") -> Angus Chuck Flap Tail
B15: Highest Retail Value/Srv | C15: =MAX('Menu Data'!Q4:Q41) -> 9.69
B17: CATEGORY BREAKDOWN (average retail value per serving, by category)
B18: Category | C18: Item Count | D18: Avg Calories | E18: Avg Value/Serving ($) | F18: Total Value ($) | G18: Notes
B19: Beef | C19: =COUNTIF('Menu Data'!C4:C86,"Beef") -> 9 | D19: =IFERROR(AVERAGEIF('Menu Data'!C4:C86,"Beef",'Menu Data'!D4:D86),"") -> 246.66667 | E19: =AVERAGEIF('Menu Data'!C4:C12,"Beef",'Menu Data'!Q4:Q12) -> 4.6122222 | F19: =SUMIF('Menu Data'!C4:C12,"Beef",'Menu Data'!Q4:Q12) -> 41.51
B20: Pork | C20: =COUNTIF('Menu Data'!C4:C86,"Pork") -> 6 | D20: =IFERROR(AVERAGEIF('Menu Data'!C4:C86,"Pork",'Menu Data'!D4:D86),"") -> 310 | E20: =AVERAGEIF('Menu Data'!C16:C21,"Pork",'Menu Data'!Q16:Q21) -> 1.7066667 | F20: =SUMIF('Menu Data'!C16:C21,"Pork",'Menu Data'!Q16:Q21) -> 10.24
B21: Chicken | C21: =COUNTIF('Menu Data'!C4:C86,"Chicken") -> 3 | D21: =IFERROR(AVERAGEIF('Menu Data'!C4:C86,"Chicken",'Menu Data'!D4:D86),"") -> 133.33333 | E21: =AVERAGEIF('Menu Data'!C13:C15,"Chicken",'Menu Data'!Q13:Q15) -> 1.44 | F21: =SUMIF('Menu Data'!C13:C15,"Chicken",'Menu Data'!Q13:Q15) -> 4.32
B22: Seafood | C22: =COUNTIF('Menu Data'!C4:C86,"Seafood") -> 7 | D22: =IFERROR(AVERAGEIF('Menu Data'!C4:C86,"Seafood",'Menu Data'!D4:D86),"") -> 104.28571 | E22: =AVERAGEIF('Menu Data'!C22:C28,"Seafood",'Menu Data'!Q22:Q28) -> 2.0828571 | F22: =SUMIF('Menu Data'!C22:C28,"Seafood",'Menu Data'!Q22:Q28) -> 14.58
B23: Vegetable | C23: =COUNTIF('Menu Data'!C4:C86,"Vegetable") -> 12 | D23: =IFERROR(AVERAGEIF('Menu Data'!C4:C86,"Vegetable",'Menu Data'!D4:D86),"") -> 40 | E23: =AVERAGEIF('Menu Data'!C29:C40,"Vegetable",'Menu Data'!Q29:Q40) -> 0.87 | F23: =SUMIF('Menu Data'!C29:C40,"Vegetable",'Menu Data'!Q29:Q40) -> 10.44
B24: Rice | C24: =COUNTIF('Menu Data'!C4:C86,"Rice") -> 1 | D24: =IFERROR(AVERAGEIF('Menu Data'!C4:C86,"Rice",'Menu Data'!D4:D86),"") -> 110 | E24: =AVERAGEIF('Menu Data'!C41,"Rice",'Menu Data'!Q41) -> 0.23 | F24: =SUMIF('Menu Data'!C41,"Rice",'Menu Data'!Q41) -> 0.23
B26: SCENARIO ANALYSIS - Cost Recovery Ratio
B27: Scenario | C27: Meat Servings | D27: Side Servings (Vegetables / Rice) | E27: Est. Retail Value | F27: Cost Recovery Ratio | G27: Notes
B28: Casual Customer | C28: 3 | D28: 2 | E28: =ROUND(3*AVERAGE(E19:E22) + 2*AVERAGE(E23:E24),2) -> 8.48 | F28: =ROUND(E28/$C$4,2) -> 0.21 | G28: 3 meat + 2 side servings at avg value
B29: Average Customer | C29: 6 | D29: 3 | E29: =ROUND(6*AVERAGE(E19:E22) + 3*AVERAGE(E23:E24),2) -> 16.41 | F29: =ROUND(E29/$C$4,2) -> 0.42 | G29: 6 meat + 3 side servings at avg value
B30: Competitive Buffet Customer | C30: 10 | D30: 4 | E30: =ROUND(10*AVERAGE(E19:E22) + 4*AVERAGE(E23:E24),2) -> 26.8 | F30: =ROUND(E30/$C$4,2) -> 0.68 | G30: 10 meat servings + 4 side servings at avg value
